<?xml version="1.0"?>
<robot xmlns:xacro="http://www.ros.org/wiki/xacro">

  <xacro:macro name="omnibot" params="prefix">

    <!-- Base Link -->
    <link name="${prefix}base_link">
    <!-- <inertial>
      <origin xyz="-0.010114084351277176 0.08582006309919016 0.05158126088553053" rpy="0 0 0"/>
      <mass value="1.5472964927177257"/>
      <inertia ixx="0.006814" iyy="0.006815" izz="0.01194" ixy="1e-06" iyz="-2.1e-05" ixz="2.1e-05"/>
    </inertial> -->
    <visual>
      <origin xyz="0 0 0" rpy="0 0 0"/>
      <geometry>
        <mesh filename="file://$(find omni_drive_arduino)/meshes/base_link.stl" scale="0.001 0.001 0.001"/>
      </geometry>
      <material name="silver"/>
    </visual>
    <collision>
      <origin xyz="0 0 0" rpy="0 0 0"/>
      <geometry>
        <mesh filename="file://$(find omni_drive_arduino)/meshes/base_link.stl" scale="0.001 0.001 0.001"/>
      </geometry>
    </collision>
    </link>

    <!-- first wheel Link -->
    <link name="${prefix}first_wheel">
    <inertial>
      <origin xyz="-0.008838754757050732 0.00883870623777197 -3.5401586982383715e-07" rpy="0 0 0"/>
      <mass value="0.4662565284394176"/>
      <inertia ixx="0.000144" iyy="0.000144" izz="0.000112" ixy="-3.2e-05" iyz="-0.0" ixz="0.0"/>
    </inertial>
    <visual>
      <origin xyz="0.090188 -0.165897 -0.029411" rpy="0 0 0"/>
      <geometry>
        <mesh filename="file://$(find omni_drive_arduino)/meshes/wheel_1_1.stl" scale="0.001 0.001 0.001"/>
      </geometry>
      <material name="silver"/>
    </visual>
    <collision>
      <origin xyz="0.090188 -0.165897 -0.029411" rpy="0 0 0"/>
      <geometry>
        <mesh filename="file://$(find omni_drive_arduino)/meshes/wheel_1_1.stl" scale="0.001 0.001 0.001"/>
      </geometry>
    </collision>
    </link>

    <!-- second wheel Link -->
    <link name="${prefix}second_wheel">
      <inertial>
        <origin xyz="0.008838662424130797 0.008838700986665754 -3.540158698273066e-07" rpy="0 0 0"/>
        <mass value="0.4662565284394172"/>
        <inertia ixx="0.000144" iyy="0.000144" izz="0.000112" ixy="3.2e-05" iyz="-0.0" ixz="-0.0"/>
      </inertial>
      <visual>
        <origin xyz="-0.071606 -0.165897 -0.029411" rpy="0 0 0"/>
        <geometry>
          <mesh filename="file://$(find omni_drive_arduino)/meshes/wheel_2_1.stl" scale="0.001 0.001 0.001"/>
        </geometry>
        <material name="silver"/>
      </visual>
      <collision>
        <origin xyz="-0.071606 -0.165897 -0.029411" rpy="0 0 0"/>
        <geometry>
          <mesh filename="file://$(find omni_drive_arduino)/meshes/wheel_2_1.stl" scale="0.001 0.001 0.001"/>
        </geometry>
      </collision>    
    </link>

    <!-- third wheel Link -->
    <link name="${prefix}third_wheel">
      <inertial>
        <origin xyz="0.008838657854423254 -0.008838698794982992 -3.540158718083608e-07" rpy="0 0 0"/>
        <mass value="0.46625652843941695"/>
        <inertia ixx="0.000144" iyy="0.000144" izz="0.000112" ixy="-3.2e-05" iyz="-0.0" ixz="0.0"/>
      </inertial>
      <visual>
        <origin xyz="-0.071606 -0.004103 -0.029411" rpy="0 0 0"/>
        <geometry>
          <mesh filename="file://$(find omni_drive_arduino)/meshes/wheel_3_1.stl" scale="0.001 0.001 0.001"/>
        </geometry>
        <material name="silver"/>
      </visual>
      <collision>
        <origin xyz="-0.071606 -0.004103 -0.029411" rpy="0 0 0"/>
        <geometry>
          <mesh filename="file://$(find omni_drive_arduino)/meshes/wheel_3_1.stl" scale="0.001 0.001 0.001"/>
        </geometry>
      </collision>
    </link>

    <!-- fourth wheel Link -->
    <link name="${prefix}fourth_wheel">
      <inertial>
        <origin xyz="-0.008838851711757023 -0.008838538089336623 -3.54015869799551e-07" rpy="0 0 0"/>
        <mass value="0.4662565284394167"/>
        <inertia ixx="0.000144" iyy="0.000144" izz="0.000112" ixy="3.2e-05" iyz="0.0" ixz="0.0"/>
      </inertial>
      <visual>
        <origin xyz="0.090188 -0.004103 -0.029411" rpy="0 0 0"/>
        <geometry>
          <mesh filename="file://$(find omni_drive_arduino)/meshes/wheel_4_1.stl" scale="0.001 0.001 0.001"/>
        </geometry>
        <material name="silver"/>
      </visual>
      <collision>
        <origin xyz="0.090188 -0.004103 -0.029411" rpy="0 0 0"/>
        <geometry>
          <mesh filename="file://$(find omni_drive_arduino)/meshes/wheel_4_1.stl" scale="0.001 0.001 0.001"/>
        </geometry>
      </collision>
    </link>

    <!-- first wheel joint -->
    <joint name="${prefix}first_wheel_joint" type="continuous">
      <origin xyz="-0.090188 0.165897 0.029411" rpy="0 0 0"/>
      <parent link="${prefix}base_link"/>
      <child link="${prefix}first_wheel"/>
      <axis xyz="0.707107 -0.707107 -0.0"/>
    </joint>

    <!-- second wheel joint -->
    <joint name="${prefix}second_wheel_joint" type="continuous">
      <origin xyz="0.071606 0.165897 0.029411" rpy="0 0 0"/>
      <parent link="${prefix}base_link"/>
      <child link="${prefix}second_wheel"/>
      <axis xyz="-0.707107 -0.707106 -0.0"/>
    </joint>

    <!-- third wheel joint -->
    <joint name="${prefix}third_wheel_joint" type="continuous">
      <origin xyz="0.071606 0.004103 0.029411" rpy="0 0 0"/>
      <parent link="${prefix}base_link"/>
      <child link="${prefix}third_wheel"/>
      <axis xyz="0.707107 -0.707106 0.0"/>
    </joint>

    <!-- fourth wheel joint -->
    <joint name="${prefix}fourth_wheel_joint" type="continuous">
      <origin xyz="-0.090188 0.004103 0.029411" rpy="0 0 0"/>
      <parent link="${prefix}base_link"/>
      <child link="${prefix}fourth_wheel"/>
      <axis xyz="0.707107 0.707106 -0.0"/>
    </joint>

  </xacro:macro>

</robot>
